<?xml version="1.0" encoding="utf-8"?>
<mujoco>
	<compiler angle="radian" coordinate="local" meshdir="../stls/fetch" texturedir="../textures"></compiler>
	<option timestep="0.002">
		<flag warmstart="enable"></flag>
	</option>

	<include file="shared.xml"></include>
	<include file="../stls/objects/assets/drawer_dependencies.xml"/>
    <include file="../stls/objects/assets/block_dependencies.xml"/>
	<worldbody>
		<geom name="floor0" pos="0.8 0.75 0" size="0.85 0.7 1" type="plane" condim="3" material="floor_mat"></geom>
		<body name="floor0" pos="0.8 0.75 0">
			<site name="target0" pos="0 0 0.5" size="0.02 0.02 0.02" rgba="1 0 0 1" type="sphere"></site>
		</body>

		<include file="robot.xml"></include>
		
		<body pos="1.3 0.75 0.2" name="table0">
			<geom size="0.25 0.35 0.2" type="box" mass="2000" material="table_mat"></geom>
		</body>
		
		<body name="object0" pos="0.025 0.025 0.025">
			<!-- Daniel: 
				I had to add the following line with inertial data in order to get the drawer env to work.
				This line is not present in the original pick_and_place.xml file. 
				I have no idea why I needed to add it but noting this down here for future reference.
			-->
			<inertial mass="0.001" diaginertia="0.001 0.001 0.001" pos="0.0 0 0"/>
			<!-- ^ That's the line I added. -->
			<joint name="object0:joint" type="free" damping="0.01"></joint>
			<geom size="0.025 0.025 0.025" type="box" condim="3" name="object0" material="block_mat" mass="2" solimp="0.999 0.9999 0.001 0.5 2"></geom>
			<site name="object0" pos="0 0 0" size="0.02 0.02 0.02" rgba="1 0 0 1" type="sphere"></site>
		</body>

        <body name="drawer" pos="1.3 1.15 0.40" childclass="drawer_base">
			<body name="drawercase_link" pos="0 0 0.084">
				<geom material="drawer_beige" mesh="drawercase"/>
				<geom class="drawer_col" pos="-0.11 0 0" size="0.008 0.1 0.084" type="box" mass=".05"/>
				<geom class="drawer_col" pos="0.11 0 0" size="0.008 0.1 0.084" type="box" mass=".05"/>
				<geom class="drawer_col" pos="0 0.092 -0.008" size="0.102 0.008 0.076" type="box" mass=".05"/>
				<geom class="drawer_col" pos="0 -0.008 -0.07" size="0.102 0.092 0.014" type="box" mass=".05"/>
				<geom class="drawer_col" pos="0 0 0.076" size="0.102 0.1 0.008" type="box" mass=".05"/>
				<body name="drawer_link" pos="0 -0.01 0.006">
					<joint type="slide" range="-0.16 0" axis="0 1 0" name="goal_slidey" pos="0 0 0" damping="2" solimplimit="0.999 0.9999 0.001 0.5 2"/>
					<geom material="drawer_beige" mesh="drawer"/>
					<geom material="drawer_white" mesh="drawerhandle" pos="0 -0.114 0" name="objGeom"/>
					<!-- Adding additional tracking points -->
					<site name="drawer_handle" pos="0 -0.148 0" size="0.02 0.02 0.02" rgba="0 0 1 1" type="sphere" />
					<site name="drawer_volume_min" pos="-0.09 -0.08 -0.06" size="0.02 0.02 0.02" rgba="0 0 1 1" type="sphere" />
					<site name="drawer_volume_max" pos="0.09 0.08 0.06" size="0.02 0.02 0.02" rgba="0 0 1 1" type="sphere" />                                
					<geom class="drawer_col" pos="0 -0.082 0.008" size="0.1 0.008 0.052" type="box" mass=".04"/>
					<geom class="drawer_col" pos="0 0.082 0.008" size="0.1 0.008 0.052" type="box" mass=".04"/>
					<geom class="drawer_col" pos="-0.092 0 0.008" size="0.008 0.074 0.052" type="box" mass=".04"/>
					<geom class="drawer_col" pos="0.092 0 0.008" size="0.008 0.074 0.052" type="box" mass=".04"/>
					<geom class="drawer_col" pos="0 0 -0.052" size="0.1 0.09 0.008" type="box" mass=".04"/>
					<geom class="drawer_col" euler="1.571 0 0" pos="-0.05 -0.12 0.0" size="0.009 0.03" type="capsule" mass=".06"/>
					<geom class="drawer_col" euler="0 1.57 0" pos="0 -0.15 0" size="0.009 0.05" type="capsule" mass=".06"/>
					<geom class="drawer_col" euler="1.57 0 0" pos="0.05 -0.12 0" size="0.009 0.03" type="capsule" mass=".06"/>
				</body>
			</body>
		</body>

		<!-- 
		We can put this block in to debug positions 
		
		<body name="block" childclass="block_base" pos="1.0 1.0 1.0">
			<freejoint/>
			<geom material="block_wood" pos="0 0 .02" mesh="block"/>
			<geom name="blockGeom" class="block_col" pos="0 0 .02" size="0.02 0.02 0.02" type="box" mass=".1"/>
		</body> 
		!-->

		<light directional="true" ambient="0.2 0.2 0.2" diffuse="0.8 0.8 0.8" specular="0.3 0.3 0.3" castshadow="false" pos="0 0 4" dir="0 0 -1" name="light0"></light>
	</worldbody>

	<actuator>
		<position ctrllimited="true" ctrlrange="0 0.2" joint="robot0:l_gripper_finger_joint" kp="30000" name="robot0:l_gripper_finger_joint" user="1"></position>
		<position ctrllimited="true" ctrlrange="0 0.2" joint="robot0:r_gripper_finger_joint" kp="30000" name="robot0:r_gripper_finger_joint" user="1"></position>
	</actuator>
</mujoco>
